[2025-05-11T03:07:45.120+0700] {local_task_job_runner.py:120} INFO - ::group::Pre task execution logs
[2025-05-11T03:07:45.160+0700] {taskinstance.py:2076} INFO - Dependencies all met for dep_context=non-requeueable deps ti=<TaskInstance: data_transformation.run_dbt_staging scheduled__2025-05-09T17:00:00+00:00 [queued]>
[2025-05-11T03:07:45.170+0700] {taskinstance.py:2076} INFO - Dependencies all met for dep_context=requeueable deps ti=<TaskInstance: data_transformation.run_dbt_staging scheduled__2025-05-09T17:00:00+00:00 [queued]>
[2025-05-11T03:07:45.170+0700] {taskinstance.py:2306} INFO - Starting attempt 6 of 6
[2025-05-11T03:07:45.190+0700] {taskinstance.py:2330} INFO - Executing <Task(BashOperator): run_dbt_staging> on 2025-05-09 17:00:00+00:00
[2025-05-11T03:07:45.194+0700] {standard_task_runner.py:63} INFO - Started process 3199 to run task
[2025-05-11T03:07:45.197+0700] {standard_task_runner.py:90} INFO - Running: ['***', 'tasks', 'run', 'data_transformation', 'run_dbt_staging', 'scheduled__2025-05-09T17:00:00+00:00', '--job-id', '49', '--raw', '--subdir', 'DAGS_FOLDER/data_transformation.py', '--cfg-path', '/tmp/tmp8ch1ovl6']
[2025-05-11T03:07:45.199+0700] {standard_task_runner.py:91} INFO - Job 49: Subtask run_dbt_staging
[2025-05-11T03:07:45.268+0700] {task_command.py:426} INFO - Running <TaskInstance: data_transformation.run_dbt_staging scheduled__2025-05-09T17:00:00+00:00 [running]> on host f94ba298fced
[2025-05-11T03:07:45.512+0700] {taskinstance.py:2648} INFO - Exporting env vars: AIRFLOW_CTX_DAG_OWNER='***' AIRFLOW_CTX_DAG_ID='data_transformation' AIRFLOW_CTX_TASK_ID='run_dbt_staging' AIRFLOW_CTX_EXECUTION_DATE='2025-05-09T17:00:00+00:00' AIRFLOW_CTX_TRY_NUMBER='6' AIRFLOW_CTX_DAG_RUN_ID='scheduled__2025-05-09T17:00:00+00:00'
[2025-05-11T03:07:45.513+0700] {taskinstance.py:430} INFO - ::endgroup::
[2025-05-11T03:07:45.526+0700] {subprocess.py:63} INFO - Tmp dir root location: /tmp
[2025-05-11T03:07:45.528+0700] {subprocess.py:75} INFO - Running command: ['/usr/bin/bash', '-c', 'cd /opt/***/dbt && dbt run --profiles-dir /opt/***/dbt --select staging --exclude stg_stock_predictions model_performance_metrics']
[2025-05-11T03:07:45.538+0700] {subprocess.py:86} INFO - Output:
[2025-05-11T03:07:48.376+0700] {subprocess.py:93} INFO - [0m20:07:48  Running with dbt=1.9.4
[2025-05-11T03:07:48.885+0700] {subprocess.py:93} INFO - [0m20:07:48  Registered adapter: postgres=1.9.0
[2025-05-11T03:07:50.815+0700] {subprocess.py:93} INFO - [0m20:07:50  Encountered an error:
[2025-05-11T03:07:50.816+0700] {subprocess.py:93} INFO - Compilation Error
[2025-05-11T03:07:50.817+0700] {subprocess.py:93} INFO -   Model 'model.idx_stock.lstm_performance_metrics' (models/marts/analytics/lstm_performance_metrics.sql) depends on a source named 'public.model_performance_metrics' which was not found
[2025-05-11T03:07:52.467+0700] {subprocess.py:97} INFO - Command exited with return code 2
[2025-05-11T03:07:52.469+0700] {taskinstance.py:441} INFO - ::group::Post task execution logs
[2025-05-11T03:07:52.509+0700] {taskinstance.py:2905} ERROR - Task failed with exception
Traceback (most recent call last):
  File "/home/airflow/.local/lib/python3.12/site-packages/airflow/models/taskinstance.py", line 465, in _execute_task
    result = _execute_callable(context=context, **execute_callable_kwargs)
             ^^^^^^^^^^^^^^^^^^^^^^^^^^^^^^^^^^^^^^^^^^^^^^^^^^^^^^^^^^^^^
  File "/home/airflow/.local/lib/python3.12/site-packages/airflow/models/taskinstance.py", line 432, in _execute_callable
    return execute_callable(context=context, **execute_callable_kwargs)
           ^^^^^^^^^^^^^^^^^^^^^^^^^^^^^^^^^^^^^^^^^^^^^^^^^^^^^^^^^^^^
  File "/home/airflow/.local/lib/python3.12/site-packages/airflow/models/baseoperator.py", line 401, in wrapper
    return func(self, *args, **kwargs)
           ^^^^^^^^^^^^^^^^^^^^^^^^^^^
  File "/home/airflow/.local/lib/python3.12/site-packages/airflow/operators/bash.py", line 243, in execute
    raise AirflowException(
airflow.exceptions.AirflowException: Bash command failed. The command returned a non-zero exit code 2.
[2025-05-11T03:07:52.526+0700] {taskinstance.py:1206} INFO - Marking task as FAILED. dag_id=data_transformation, task_id=run_dbt_staging, run_id=scheduled__2025-05-09T17:00:00+00:00, execution_date=20250509T170000, start_date=20250510T200745, end_date=20250510T200752
[2025-05-11T03:07:52.547+0700] {standard_task_runner.py:110} ERROR - Failed to execute job 49 for task run_dbt_staging (Bash command failed. The command returned a non-zero exit code 2.; 3199)
[2025-05-11T03:07:52.595+0700] {local_task_job_runner.py:240} INFO - Task exited with return code 1
[2025-05-11T03:07:52.640+0700] {taskinstance.py:3503} INFO - 0 downstream tasks scheduled from follow-on schedule check
[2025-05-11T03:07:52.650+0700] {local_task_job_runner.py:222} INFO - ::endgroup::
