[2025-05-11T03:00:20.119+0700] {local_task_job_runner.py:120} INFO - ::group::Pre task execution logs
[2025-05-11T03:00:20.163+0700] {taskinstance.py:2076} INFO - Dependencies all met for dep_context=non-requeueable deps ti=<TaskInstance: data_transformation.run_dbt_staging scheduled__2025-05-09T17:00:00+00:00 [queued]>
[2025-05-11T03:00:20.174+0700] {taskinstance.py:2076} INFO - Dependencies all met for dep_context=requeueable deps ti=<TaskInstance: data_transformation.run_dbt_staging scheduled__2025-05-09T17:00:00+00:00 [queued]>
[2025-05-11T03:00:20.175+0700] {taskinstance.py:2306} INFO - Starting attempt 4 of 5
[2025-05-11T03:00:20.195+0700] {taskinstance.py:2330} INFO - Executing <Task(BashOperator): run_dbt_staging> on 2025-05-09 17:00:00+00:00
[2025-05-11T03:00:20.201+0700] {standard_task_runner.py:63} INFO - Started process 2726 to run task
[2025-05-11T03:00:20.203+0700] {standard_task_runner.py:90} INFO - Running: ['***', 'tasks', 'run', 'data_transformation', 'run_dbt_staging', 'scheduled__2025-05-09T17:00:00+00:00', '--job-id', '40', '--raw', '--subdir', 'DAGS_FOLDER/data_transformation.py', '--cfg-path', '/tmp/tmphynn_5z2']
[2025-05-11T03:00:20.206+0700] {standard_task_runner.py:91} INFO - Job 40: Subtask run_dbt_staging
[2025-05-11T03:00:20.283+0700] {task_command.py:426} INFO - Running <TaskInstance: data_transformation.run_dbt_staging scheduled__2025-05-09T17:00:00+00:00 [running]> on host f94ba298fced
[2025-05-11T03:00:20.589+0700] {taskinstance.py:2648} INFO - Exporting env vars: AIRFLOW_CTX_DAG_OWNER='***' AIRFLOW_CTX_DAG_ID='data_transformation' AIRFLOW_CTX_TASK_ID='run_dbt_staging' AIRFLOW_CTX_EXECUTION_DATE='2025-05-09T17:00:00+00:00' AIRFLOW_CTX_TRY_NUMBER='4' AIRFLOW_CTX_DAG_RUN_ID='scheduled__2025-05-09T17:00:00+00:00'
[2025-05-11T03:00:20.590+0700] {taskinstance.py:430} INFO - ::endgroup::
[2025-05-11T03:00:20.606+0700] {subprocess.py:63} INFO - Tmp dir root location: /tmp
[2025-05-11T03:00:20.607+0700] {subprocess.py:75} INFO - Running command: ['/usr/bin/bash', '-c', 'cd /opt/***/dbt && dbt run --profiles-dir /opt/***/dbt --select marts.analytics --exclude lstm_performance_metrics model_performance_metrics stock_prediction_dashboard']
[2025-05-11T03:00:20.618+0700] {subprocess.py:86} INFO - Output:
[2025-05-11T03:00:23.580+0700] {subprocess.py:93} INFO - [0m20:00:23  Running with dbt=1.9.4
[2025-05-11T03:00:23.996+0700] {subprocess.py:93} INFO - [0m20:00:23  Registered adapter: postgres=1.9.0
[2025-05-11T03:00:25.356+0700] {subprocess.py:93} INFO - [0m20:00:25  Encountered an error:
[2025-05-11T03:00:25.357+0700] {subprocess.py:93} INFO - Compilation Error
[2025-05-11T03:00:25.358+0700] {subprocess.py:93} INFO -   Model 'model.idx_stock.lstm_performance_metrics' (models/marts/analytics/lstm_performance_metrics.sql) depends on a source named 'public.model_performance_metrics' which was not found
[2025-05-11T03:00:26.992+0700] {subprocess.py:97} INFO - Command exited with return code 2
[2025-05-11T03:00:26.993+0700] {taskinstance.py:441} INFO - ::group::Post task execution logs
[2025-05-11T03:00:27.009+0700] {taskinstance.py:2905} ERROR - Task failed with exception
Traceback (most recent call last):
  File "/home/airflow/.local/lib/python3.12/site-packages/airflow/models/taskinstance.py", line 465, in _execute_task
    result = _execute_callable(context=context, **execute_callable_kwargs)
             ^^^^^^^^^^^^^^^^^^^^^^^^^^^^^^^^^^^^^^^^^^^^^^^^^^^^^^^^^^^^^
  File "/home/airflow/.local/lib/python3.12/site-packages/airflow/models/taskinstance.py", line 432, in _execute_callable
    return execute_callable(context=context, **execute_callable_kwargs)
           ^^^^^^^^^^^^^^^^^^^^^^^^^^^^^^^^^^^^^^^^^^^^^^^^^^^^^^^^^^^^
  File "/home/airflow/.local/lib/python3.12/site-packages/airflow/models/baseoperator.py", line 401, in wrapper
    return func(self, *args, **kwargs)
           ^^^^^^^^^^^^^^^^^^^^^^^^^^^
  File "/home/airflow/.local/lib/python3.12/site-packages/airflow/operators/bash.py", line 243, in execute
    raise AirflowException(
airflow.exceptions.AirflowException: Bash command failed. The command returned a non-zero exit code 2.
[2025-05-11T03:00:27.015+0700] {taskinstance.py:1206} INFO - Marking task as UP_FOR_RETRY. dag_id=data_transformation, task_id=run_dbt_staging, run_id=scheduled__2025-05-09T17:00:00+00:00, execution_date=20250509T170000, start_date=20250510T200020, end_date=20250510T200027
[2025-05-11T03:00:27.034+0700] {standard_task_runner.py:110} ERROR - Failed to execute job 40 for task run_dbt_staging (Bash command failed. The command returned a non-zero exit code 2.; 2726)
[2025-05-11T03:00:27.068+0700] {local_task_job_runner.py:240} INFO - Task exited with return code 1
[2025-05-11T03:00:27.101+0700] {taskinstance.py:3503} INFO - 0 downstream tasks scheduled from follow-on schedule check
[2025-05-11T03:00:27.108+0700] {local_task_job_runner.py:222} INFO - ::endgroup::
